Workbook
Name 割引内訳リスト: 割引リスト[割引リスト]

Sheet R7_入館者
A1: 日付 | B1: 入館者コード | C1: 入館者分類 | D1: 割引リスト | E1: 入場者数 | F1: 入館料単価 | G1: 入館料合計 | H1: 展覧会名
A2: 45748 | B2: B：シニア | C2: シニア | E2: 5 | F2: =IF(C2="","",IFERROR(VLOOKUP(C2,[1]リスト!$B$3:$C$17,2,FALSE),"")) | G2: =IF(OR(E2="",F2=""),"",E2*F2) | H2: 1_春季展_前期
A3: 45748 | B3: C：学生 | C3: 学生 | E3: 1 | F3: =IF(C3="","",IFERROR(VLOOKUP(C3,[1]リスト!$B$3:$C$17,2,FALSE),"")) | G3: =IF(OR(E3="",F3=""),"",E3*F3) | H3: 1_春季展_前期
A4: 45749 | B4: A：一般 | C4: 一般 | E4: 1 | F4: =IF(C4="","",IFERROR(VLOOKUP(C4,[1]リスト!$B$3:$C$17,2,FALSE),"")) | G4: =IF(OR(E4="",F4=""),"",E4*F4) | H4: 1_春季展_前期
A5: 45749 | B5: B：シニア | C5: シニア | E5: 9 | F5: =IF(C5="","",IFERROR(VLOOKUP(C5,[1]リスト!$B$3:$C$17,2,FALSE),"")) | G5: =IF(OR(E5="",F5=""),"",E5*F5) | H5: 1_春季展_前期
A6: 45750 | B6: A：一般 | C6: 一般 | E6: 3 | F6: =IF(C6="","",IFERROR(VLOOKUP(C6,[1]リスト!$B$3:$C$17,2,FALSE),"")) | G6: =IF(OR(E6="",F6=""),"",E6*F6) | H6: 1_春季展_前期
A7: 45750 | B7: B：シニア | C7: シニア（割引） | D7: 優待割引 | E7: 3 | F7: =IF(C7="","",IFERROR(VLOOKUP(C7,[1]リスト!$B$3:$C$17,2,FALSE),"")) | G7: =IF(OR(E7="",F7=""),"",E7*F7) | H7: 1_春季展_前期
A8: 45751 | B8: B：シニア | C8: シニア | E8: 3 | F8: =IF(C8="","",IFERROR(VLOOKUP(C8,[1]リスト!$B$3:$C$17,2,FALSE),"")) | G8: =IF(OR(E8="",F8=""),"",E8*F8) | H8: 1_春季展_前期
A9: 45751 | B9: A：一般 | C9: 一般（特別優待） | D9: 特別優待割引 | E9: 2 | F9: =IF(C9="","",IFERROR(VLOOKUP(C9,[1]リスト!$B$3:$C$17,2,FALSE),"")) | G9: =IF(OR(E9="",F9=""),"",E9*F9) | H9: 1_春季展_前期
A10: 45751 | B10: F：招待券 | C10: 招待券 | E10: 2 | F10: =IF(C10="","",IFERROR(VLOOKUP(C10,[1]リスト!$B$3:$C$17,2,FALSE),"")) | G10: =IF(OR(E10="",F10=""),"",E10*F10) | H10: 1_春季展_前期
A11: 45752 | B11: A：一般 | C11: 一般 | E11: 2 | F11: =IF(C11="","",IFERROR(VLOOKUP(C11,[1]リスト!$B$3:$C$17,2,FALSE),"")) | G11: =IF(OR(E11="",F11=""),"",E11*F11) | H11: 1_春季展_前期
A12: 45752 | B12: A：一般 | C12: 一般（割引） | D12: HP | E12: 1 | F12: =IF(C12="","",IFERROR(VLOOKUP(C12,[1]リスト!$B$3:$C$17,2,FALSE),"")) | G12: =IF(OR(E12="",F12=""),"",E12*F12) | H12: 1_春季展_前期
A13: 45752 | B13: B：シニア | C13: シニア | E13: 3 | F13: =IF(C13="","",IFERROR(VLOOKUP(C13,[1]リスト!$B$3:$C$17,2,FALSE),"")) | G13: =IF(OR(E13="",F13=""),"",E13*F13) | H13: 1_春季展_前期
A14: 45752 | B14: B：シニア | C14: シニア（割引） | D14: HP | E14: 1 | F14: =IF(C14="","",IFERROR(VLOOKUP(C14,[1]リスト!$B$3:$C$17,2,FALSE),"")) | G14: =IF(OR(E14="",F14=""),"",E14*F14) | H14: 1_春季展_前期
A15: 45752 | B15: F：招待券 | C15: 招待券 | E15: 2 | F15: =IF(C15="","",IFERROR(VLOOKUP(C15,[1]リスト!$B$3:$C$17,2,FALSE),"")) | G15: =IF(OR(E15="",F15=""),"",E15*F15) | H15: 1_春季展_前期
A16: 45753 | B16: A：一般 | C16: 一般 | E16: 2 | F16: =IF(C16="","",IFERROR(VLOOKUP(C16,[1]リスト!$B$3:$C$17,2,FALSE),"")) | G16: =IF(OR(E16="",F16=""),"",E16*F16) | H16: 1_春季展_前期
A17: 45753 | B17: B：シニア | C17: シニア | E17: 1 | F17: =IF(C17="","",IFERROR(VLOOKUP(C17,[1]リスト!$B$3:$C$17,2,FALSE),"")) | G17: =IF(OR(E17="",F17=""),"",E17*F17) | H17: 1_春季展_前期
A18: 45753 | B18: B：シニア | C18: シニア（割引） | D18: 優待割引 | E18: 1 | F18: =IF(C18="","",IFERROR(VLOOKUP(C18,[1]リスト!$B$3:$C$17,2,FALSE),"")) | G18: =IF(OR(E18="",F18=""),"",E18*F18) | H18: 1_春季展_前期
A19: 45755 | B19: A：一般 | C19: 一般 | E19: 2 | F19: =IF(C19="","",IFERROR(VLOOKUP(C19,[1]リスト!$B$3:$C$17,2,FALSE),"")) | G19: =IF(OR(E19="",F19=""),"",E19*F19) | H19: 1_春季展_前期
A20: 45755 | B20: B：シニア | C20: シニア | E20: 1 | F20: =IF(C20="","",IFERROR(VLOOKUP(C20,[1]リスト!$B$3:$C$17,2,FALSE),"")) | G20: =IF(OR(E20="",F20=""),"",E20*F20) | H20: 1_春季展_前期
A21: 45755 | B21: C：学生 | C21: 学生 | E21: 2 | F21: =IF(C21="","",IFERROR(VLOOKUP(C21,[1]リスト!$B$3:$C$17,2,FALSE),"")) | G21: =IF(OR(E21="",F21=""),"",E21*F21) | H21: 1_春季展_前期
A22: 45756 | B22: A：一般 | C22: 一般 | E22: 1 | F22: =IF(C22="","",IFERROR(VLOOKUP(C22,[1]リスト!$B$3:$C$17,2,FALSE),"")) | G22: =IF(OR(E22="",F22=""),"",E22*F22) | H22: 1_春季展_前期
A23: 45756 | B23: B：シニア | C23: シニア | E23: 3 | F23: =IF(C23="","",IFERROR(VLOOKUP(C23,[1]リスト!$B$3:$C$17,2,FALSE),"")) | G23: =IF(OR(E23="",F23=""),"",E23*F23) | H23: 1_春季展_前期
A24: 45757 | B24: A：一般 | C24: 一般（割引） | D24: HP | E24: 2 | F24: =IF(C24="","",IFERROR(VLOOKUP(C24,[1]リスト!$B$3:$C$17,2,FALSE),"")) | G24: =IF(OR(E24="",F24=""),"",E24*F24) | H24: 1_春季展_前期
A25: 45757 | B25: B：シニア | C25: シニア | E25: 2 | F25: =IF(C25="","",IFERROR(VLOOKUP(C25,[1]リスト!$B$3:$C$17,2,FALSE),"")) | G25: =IF(OR(E25="",F25=""),"",E25*F25) | H25: 1_春季展_前期
A26: 45757 | B26: F：招待券 | C26: 招待券 | E26: 2 | F26: =IF(C26="","",IFERROR(VLOOKUP(C26,[1]リスト!$B$3:$C$17,2,FALSE),"")) | G26: =IF(OR(E26="",F26=""),"",E26*F26) | H26: 1_春季展_前期
A27: 45758 | B27: B：シニア | C27: シニア | E27: 1 | F27: =IF(C27="","",IFERROR(VLOOKUP(C27,[1]リスト!$B$3:$C$17,2,FALSE),"")) | G27: =IF(OR(E27="",F27=""),"",E27*F27) | H27: 1_春季展_前期
A28: 45759 | B28: A：一般 | C28: 一般 | E28: 1 | F28: =IF(C28="","",IFERROR(VLOOKUP(C28,[1]リスト!$B$3:$C$17,2,FALSE),"")) | G28: =IF(OR(E28="",F28=""),"",E28*F28) | H28: 1_春季展_前期
A29: 45759 | B29: A：一般 | C29: 一般（割引） | D29: HP | E29: 2 | F29: =IF(C29="","",IFERROR(VLOOKUP(C29,[1]リスト!$B$3:$C$17,2,FALSE),"")) | G29: =IF(OR(E29="",F29=""),"",E29*F29) | H29: 1_春季展_前期
A30: 45759 | B30: A：一般 | C30: 一般（割引） | D30: リロクラブ | E30: 1 | F30: =IF(C30="","",IFERROR(VLOOKUP(C30,[1]リスト!$B$3:$C$17,2,FALSE),"")) | G30: =IF(OR(E30="",F30=""),"",E30*F30) | H30: 1_春季展_前期
A31: 45759 | B31: B：シニア | C31: シニア | E31: 3 | F31: =IF(C31="","",IFERROR(VLOOKUP(C31,[1]リスト!$B$3:$C$17,2,FALSE),"")) | G31: =IF(OR(E31="",F31=""),"",E31*F31) | H31: 1_春季展_前期
A32: 45759 | B32: B：シニア | C32: シニア（割引） | D32: リロクラブ | E32: 1 | F32: =IF(C32="","",IFERROR(VLOOKUP(C32,[1]リスト!$B$3:$C$17,2,FALSE),"")) | G32: =IF(OR(E32="",F32=""),"",E32*F32) | H32: 1_春季展_前期
A33: 45760 | B33: A：一般 | C33: 一般 | E33: 3 | F33: =IF(C33="","",IFERROR(VLOOKUP(C33,[1]リスト!$B$3:$C$17,2,FALSE),"")) | G33: =IF(OR(E33="",F33=""),"",E33*F33) | H33: 1_春季展_前期
A34: 45760 | B34: A：一般 | C34: 一般（割引） | D34: HP | E34: 2 | F34: =IF(C34="","",IFERROR(VLOOKUP(C34,[1]リスト!$B$3:$C$17,2,FALSE),"")) | G34: =IF(OR(E34="",F34=""),"",E34*F34) | H34: 1_春季展_前期
A35: 45760 | B35: B：シニア | C35: シニア | E35: 2 | F35: =IF(C35="","",IFERROR(VLOOKUP(C35,[1]リスト!$B$3:$C$17,2,FALSE),"")) | G35: =IF(OR(E35="",F35=""),"",E35*F35) | H35: 1_春季展_前期
A36: 45769 | B36: A：一般 | C36: 一般 | E36: 1 | F36: =IF(C36="","",IFERROR(VLOOKUP(C36,[1]リスト!$B$3:$C$17,2,FALSE),"")) | G36: =IF(OR(E36="",F36=""),"",E36*F36) | H36: 2_春季展_後期
A37: 45769 | B37: B：シニア | C37: シニア | E37: 2 | F37: =IF(C37="","",IFERROR(VLOOKUP(C37,[1]リスト!$B$3:$C$17,2,FALSE),"")) | G37: =IF(OR(E37="",F37=""),"",E37*F37) | H37: 2_春季展_後期
A38: 45770 | B38: A：一般 | C38: 一般 | E38: 1 | F38: =IF(C38="","",IFERROR(VLOOKUP(C38,[1]リスト!$B$3:$C$17,2,FALSE),"")) | G38: =IF(OR(E38="",F38=""),"",E38*F38) | H38: 2_春季展_後期
A39: 45770 | B39: B：シニア | C39: シニア | E39: 2 | F39: =IF(C39="","",IFERROR(VLOOKUP(C39,[1]リスト!$B$3:$C$17,2,FALSE),"")) | G39: =IF(OR(E39="",F39=""),"",E39*F39) | H39: 2_春季展_後期
A40: 45771 | B40: A：一般 | C40: 一般 | E40: 1 | F40: =IF(C40="","",IFERROR(VLOOKUP(C40,[1]リスト!$B$3:$C$17,2,FALSE),"")) | G40: =IF(OR(E40="",F40=""),"",E40*F40) | H40: 2_春季展_後期
...

Sheet リスト
B2: 入場者分類 | C2: 金額 | D2: 分類コード | H2: 割引リスト | I2: 割引コード
B3: 一般 | C3: 600 | D3: A：一般 | H3: HP | I3: 01
B4: 一般（割引） | C4: 500 | D4: A：一般 | H4: 優待割引 | I4: 02
B5: 一般（特別優待） | C5: 400 | D5: A：一般 | H5: 特別優待割引 | I5: 03
B6: シニア | C6: 500 | D6: B：シニア | H6: JAF | I6: 04
B7: シニア（割引） | C7: 400 | D7: B：シニア | H7: 朝日友の会 | I7: 05
B8: 学生 | C8: 500 | D8: C：学生 | H8: リロクラブ | I8: 06
B9: 学生（割引） | C9: 400 | D9: C：学生 | H9: 奈良ファンクラブ | I9: 07
B10: 小中学生 | C10: 250 | D10: D：小中学生 | H10: アートフェスタ | I10: 08
B11: 小中学生（割引） | C11: 200 | D11: D：小中学生 | H11: 団体 | I11: 09
B12: 小中学生（無料） | C12: 0 | D12: D：小中学生 | H12: その他 | I12: 10
B13: 身障者 | C13: 300 | D13: E：身障者 | H13: コンサート | I13: 11
B14: シニア（特別優待） | C14: 300 | D14: B：シニア | H14: まほろばパス | I14: 12
B15: 学生（特別優待） | C15: 300 | D15: C：学生
B16: 招待券 | C16: 0 | D16: F：招待券
B17: 学生（無料） | C17: 0 | D17: C：学生
B18: その他 | C18: 0 | D18: Z：その他
